Workbook

Sheet Cover
B2: APEX INDUSTRIAL SOLUTIONS
B3: Leveraged Buyout (LBO) Analysis | Private Equity Acquisition Model
B4: Industrial Manufacturing & Distribution | Revenue: $380mm | EBITDA: $76mm
B7: TRANSACTION OVERVIEW
B8: Parameter | C8: Entry (2024) | D8: Exit (2029E) | E8: Delta
B9: Entry EBITDA ($mm) | C9: ='Transaction Assumptions'!C5 -> 76 | D9: N/A | E9: N/A
B10: Entry EV/EBITDA Multiple | C10: ='Transaction Assumptions'!C7 -> 10 | D10: N/A | E10: N/A
B11: Enterprise Value ($mm) | C11: ='Transaction Assumptions'!C8 -> 760 | D11: ='Transaction Assumptions'!C40 -> 1270.5 | E11: +$516mm
B12: Exit EBITDA Multiple | C12: N/A | D12: ='Transaction Assumptions'!C38 -> 10.5 | E12: ='Transaction Assumptions'!C38-'Transaction Assumptions'!C7 -> 0.5
B13: Exit EBITDA ($mm) | C13: N/A | D13: N/A | E13: $121mm
B14: Total Equity Investment ($mm) | C14: ='Transaction Assumptions'!C22 -> 304 | D14: N/A | E14: N/A
B15: Equity Proceeds ($mm) | C15: N/A | D15: ='Returns Analysis'!E11 -> 875.9 | E15: N/A
B16: Money-on-Money (MoM) | C16: — | D16: =D15/'Transaction Assumptions'!C22 -> 2.88125 | E16: N/A
B17: IRR (5-year Hold) | C17: N/A | D17: ='Returns Analysis'!E13 -> 0.23542268 | E17: N/A
B18: IRR (3-year Hold) | C18: N/A | D18: ='Returns Analysis'!D13 -> 0.29172855 | E18: N/A
B21: CAPITAL STRUCTURE
B22: Tranche | C22: Amount ($mm) | D22: % of Total | E22: Pricing
B23: Revolving Credit Facility | C23: ='Transaction Assumptions'!C18 -> 0 | D23: ='Transaction Assumptions'!D18 -> 0 | E23: SOFR+200bps
B24: Term Loan A (TLA) | C24: ='Transaction Assumptions'!C19 -> 152 | D24: ='Transaction Assumptions'!D19 -> 0.2 | E24: SOFR+225bps
B25: Term Loan B (TLB) | C25: ='Transaction Assumptions'!C20 -> 228 | D25: ='Transaction Assumptions'!D20 -> 0.3 | E25: SOFR+350bps
B26: Senior Notes | C26: ='Transaction Assumptions'!C21 -> 76 | D26: ='Transaction Assumptions'!D21 -> 0.1 | E26: 7.50% Fixed
B27: Total Debt | C27: =C24+C25+C26+C23 -> 456 | D27: =D24+D25+D26+D23 -> 0.6 | E27: ~6.2% Blended
B28: Sponsor Equity | C28: ='Transaction Assumptions'!C22 -> 304 | D28: ='Transaction Assumptions'!D22 -> 0.4 | E28: N/A
B29: Total Capitalization | C29: ='Transaction Assumptions'!C8 -> 760 | D29: 1 | E29: N/A

Sheet Transaction Assumptions
B1: APEX INDUSTRIAL: TRANSACTION ASSUMPTIONS
B3: ENTRY ASSUMPTIONS
B4: LTM Revenue ($mm) | C4: 380
B5: LTM EBITDA ($mm) | C5: 76
B6: LTM EBITDA Margin | C6: =C5/C4 -> 0.2
B7: Entry EV/EBITDA Multiple | C7: 10
B8: Enterprise Value ($mm) | C8: =C5*C7 -> 760
B9: Net Debt at Close ($mm) | C9: 0
B10: Equity Value at Entry ($mm) | C10: =C8-C9 -> 760
B11: Transaction Fees ($mm) | C11: 15.2
B12: Total Uses of Cash ($mm) | C12: =C10+C11 -> 775.2
B16: SOURCES & USES OF CAPITAL
B17: Component | C17: Amount ($mm) | D17: % of Total
B18: Revolving Credit Facility | C18: 0 | D18: =C18/C24 -> 0
B19: Term Loan A | C19: 152 | D19: =C19/C24 -> 0.2
B20: Term Loan B | C20: 228 | D20: =C20/C24 -> 0.3
B21: Senior Notes | C21: 76 | D21: =C21/C24 -> 0.1
B22: Sponsor Equity | C22: 304 | D22: =C22/C24 -> 0.4
B23: Management Rollover | C23: 0 | D23: =C23/C24 -> 0
B24: Total Sources | C24: =SUM(C18:C23) -> 760 | D24: =SUM(D18:D23) -> 1
B27: DEBT PRICING & AMORTIZATION ASSUMPTIONS
B28: Term Loan A Rate (SOFR + 225bps) | C28: 0.0775
B29: Term Loan B Rate (SOFR + 350bps) | C29: 0.09
B30: Senior Notes Rate (Fixed) | C30: 0.075
B31: TLA Annual Amortization | C31: 0.05
B32: TLB Annual Amortization | C32: 0.01
B33: Cash Sweep % (excess CF) | C33: 0.5
B35: EXIT ASSUMPTIONS
B36: Exit Year | C36: 2029
B37: Hold Period (years) | C37: =C36-2024 -> 5
B38: Exit EBITDA Multiple | C38: 10.5
B39: Exit EBITDA ($mm) | C39: 121
B40: Exit Enterprise Value ($mm) | C40: =C38*C39 -> 1270.5
B41: Estimated Exit Net Debt ($mm) | C41: 122
B42: Exit Equity Value ($mm) | C42: =C40-C41 -> 1148.5

Sheet Operating Model
B1: APEX INDUSTRIAL: OPERATING MODEL (POST-ACQUISITION)
B3: INCOME STATEMENT ($mm)
B4: Line Item | C4: FY2024A | D4: FY2025E | E4: FY2026E | F4: FY2027E | G4: FY2028E | H4: FY2029E
B5: Revenue | C5: 380 | D5: 406.6 | E5: 435.1 | F5: 465.6 | G5: 498.2 | H5: 533
B6: YoY Growth | C6: N/A | D6: =(D5-C5)/C5 -> 0.07 | E6: =(E5-D5)/D5 -> 0.070093458 | F6: =(F5-E5)/E5 -> 0.070098828 | G6: =(G5-F5)/F5 -> 0.070017182 | H6: =(H5-G5)/G5 -> 0.069851465
B7: Gross Profit | C7: =C5*0.42 -> 159.6 | D7: =D5*0.428 -> 174.0248 | E7: =E5*0.436 -> 189.7036 | F7: =F5*0.444 -> 206.7264 | G7: =G5*0.452 -> 225.1864 | H7: =H5*0.46 -> 245.18
B8: Gross Margin % | C8: 0.42 | D8: 0.428 | E8: 0.436 | F8: 0.444 | G8: 0.452 | H8: 0.46
B9: EBITDA | C9: =C5*0.2 -> 76 | D9: =D5*0.21 -> 85.386 | E9: =E5*0.22 -> 95.722 | F9: =F5*0.23 -> 107.088 | G9: =G5*0.24 -> 119.568 | H9: =H5*0.227 -> 120.991
B10: EBITDA Margin % | C10: 0.2 | D10: 0.21 | E10: 0.22 | F10: 0.23 | G10: 0.24 | H10: 0.227
B11: Depreciation & Amortization | C11: 12.4 | D11: 13.4 | E11: 14.4 | F11: 15.4 | G11: 16.4 | H11: 17.4
B12: EBIT | C12: =C9-C11 -> 63.6 | D12: =D9-D11 -> 71.986 | E12: =E9-E11 -> 81.322 | F12: =F9-F11 -> 91.688 | G12: =G9-G11 -> 103.168 | H12: =H9-H11 -> 103.591
B14: DEBT SCHEDULE ($mm)
B15: Line Item | C15: FY2024A | D15: FY2025E | E15: FY2026E | F15: FY2027E | G15: FY2028E | H15: FY2029E
B16: TLA Beginning Balance | C16: 152 | D16: =C18 -> 144.4 | E16: =D18 -> 136.4 | F16: =E18 -> 128.4 | G16: =F18 -> 120.4 | H16: =G18 -> 112.4
B17: TLA Mandatory Amortization | C17: 7.6 | D17: 8 | E17: 8 | F17: 8 | G17: 8 | H17: 8
B18: TLA Ending Balance | C18: =C16-C17 -> 144.4 | D18: =D16-D17 -> 136.4 | E18: =E16-E17 -> 128.4 | F18: =F16-F17 -> 120.4 | G18: =G16-G17 -> 112.4 | H18: =H16-H17 -> 104.4
B19: TLB Beginning Balance | C19: 228 | D19: =C21 -> 225.7 | E19: =D21 -> 223.4 | F19: =E21 -> 221.1 | G19: =F21 -> 218.8 | H19: =G21 -> 216.5
B20: TLB Mandatory Amortization | C20: 2.3 | D20: 2.3 | E20: 2.3 | F20: 2.3 | G20: 2.3 | H20: 2.3
B21: TLB Ending Balance | C21: =C19-C20 -> 225.7 | D21: =D19-D20 -> 223.4 | E21: =E19-E20 -> 221.1 | F21: =F19-F20 -> 218.8 | G21: =G19-G20 -> 216.5 | H21: =H19-H20 -> 214.2
B22: Senior Notes | C22: 76 | D22: 76 | E22: 76 | F22: 76 | G22: 76 | H22: 76
B23: Total Debt (Ending) | C23: =C18+C21+C22 -> 446.1 | D23: =D18+D21+D22 -> 435.8 | E23: =E18+E21+E22 -> 425.5 | F23: =F18+F21+F22 -> 415.2 | G23: =G18+G21+G22 -> 404.9 | H23: =H18+H21+H22 -> 394.6
B24: Total Interest Expense | C24: =(C16*0.0775)+(C19*0.09)+(C22*0.075) -> 38 | D24: =(D16*0.0775)+(D19*0.09)+(D22*0.075) -> 37.204 | E24: =(E16*0.0775)+(E19*0.09)+(E22*0.075) -> 36.377 | F24: =(F16*0.0775)+(F19*0.09)+(F22*0.075) -> 35.55 | G24: =(G16*0.0775)+(G19*0.09)+(G22*0.075) -> 34.723 | H24: =(H16*0.0775)+(H19*0.09)+(H22*0.075) -> 33.896
B25: Pre-Tax Income | C25: =C12-C24 -> 25.6 | D25: =D12-D24 -> 34.782 | E25: =E12-E24 -> 44.945 | F25: =F12-F24 -> 56.138 | G25: =G12-G24 -> 68.445 | H25: =H12-H24 -> 69.695
B26: Net Income (after 25% tax) | C26: =C25*0.75 -> 19.2 | D26: =D25*0.75 -> 26.0865 | E26: =E25*0.75 -> 33.70875 | F26: =F25*0.75 -> 42.1035 | G26: =G25*0.75 -> 51.33375 | H26: =H25*0.75 -> 52.27125
B28: CREDIT STATISTICS & COVENANTS
B29: Line Item | C29: FY2024A | D29: FY2025E | E29: FY2026E | F29: FY2027E | G29: FY2028E | H29: FY2029E
B30: Total Debt / EBITDA | C30: =C23/C9 -> 5.8697368 | D30: =D23/D9 -> 5.1038812 | E30: =E23/E9 -> 4.4451641 | F30: =F23/F9 -> 3.8771851 | G30: =G23/G9 -> 3.3863576 | H30: =H23/H9 -> 3.2613996
B31: Net Debt / EBITDA | C31: =(C23-10)/C9 -> 5.7381579 | D31: =(D23-10)/D9 -> 4.986766 | E31: =(E23-10)/E9 -> 4.3406949 | F31: =(F23-10)/F9 -> 3.783804 | G31: =(G23-10)/G9 -> 3.3027231 | H31: =(H23-10)/H9 -> 3.1787488
B32: EBITDA / Interest (Coverage) | C32: =C9/C24 -> 2 | D32: =D9/D24 -> 2.2950758 | E32: =E9/E24 -> 2.631388 | F32: =F9/F24 -> 3.0123207 | G32: =G9/G24 -> 3.4434813 | H32: =H9/H24 -> 3.5694772
B33: Fixed Charge Coverage Ratio | C33: =(C9-C11)/C24 -> 1.6736842 | D33: =(D9-D11)/D24 -> 1.9348995 | E33: =(E9-E11)/E24 -> 2.2355334 | F33: =(F9-F11)/F24 -> 2.579128 | G33: =(G9-G11)/G24 -> 2.9711718 | H33: =(H9-H11)/H24 -> 3.0561423
B34: Debt Covenant (Max Net Lev) | C34: 5.5 | D34: 5 | E34: 4.5 | F34: 4 | G34: 3.5 | H34: 3.5

Sheet Returns Analysis
B1: APEX INDUSTRIAL: LBO RETURNS ANALYSIS
B3: BASE CASE RETURNS SUMMARY (5-YEAR HOLD)
B4: Metric | C4: Entry (2024) | D4: Year 3 (2027) | E4: Year 5 (2029) | F4: Year 7 (2031)
B5: Revenue ($mm) | C5: ='Operating Model'!C5 -> 380 | D5: ='Operating Model'!F5 -> 465.6 | E5: ='Operating Model'!H5 -> 533 | F5: =ROUND('Operating Model'!C5*(('Operating Model'!H5/'Operating Model'!C5)^(1/5))^7,0) -> 610
B6: EBITDA ($mm) | C6: ='Operating Model'!C9 -> 76 | D6: ='Operating Model'!F9 -> 107.088 | E6: ='Operating Model'!H9 -> 120.991 | F6: =ROUND(F5*('Operating Model'!H9/'Operating Model'!H5),0) -> 138
B7: EBITDA Margin | C7: =C6/C5 -> 0.2 | D7: =D6/D5 -> 0.23 | E7: =E6/E5 -> 0.227 | F7: =F6/F5 -> 0.22622951
B8: EV/EBITDA Exit Multiple | C8: ='Transaction Assumptions'!C7 -> 10 | D8: 10 | E8: ='Transaction Assumptions'!C38 -> 10.5 | F8: 11
B9: Enterprise Value ($mm) | C9: ='Transaction Assumptions'!C8 -> 760 | D9: =D6*D8 -> 1070.88 | E9: ='Transaction Assumptions'!C40 -> 1270.5 | F9: =F6*F8 -> 1518
B10: Less: Net Debt ($mm) | C10: =-'Operating Model'!C23 -> -446.1 | D10: =-'Operating Model'!F23 -> -415.2 | E10: =-'Operating Model'!H23 -> -394.6 | F10: =-(MAX(0,'Operating Model'!H18-8*2)+MAX(0,'Operating Model'!H21-2.3*2)+'Operating Model'!H22) -> -374
B11: Equity Value ($mm) | C11: ='Transaction Assumptions'!C22 -> 304 | D11: =D9-'Operating Model'!F23 -> 655.68 | E11: =E9-'Operating Model'!H23 -> 875.9 | F11: =F9+F10 -> 1144
B12: Money-on-Money (MoM) | C12: =C11/'Transaction Assumptions'!C22 -> 1 | D12: =D11/'Transaction Assumptions'!C22 -> 2.1568421 | E12: =E11/'Transaction Assumptions'!C22 -> 2.88125 | F12: =F11/'Transaction Assumptions'!C22 -> 3.7631579
B13: IRR (from Entry) | C13: N/A | D13: =XIRR(C53:D53,C54:D54) -> 0.29172855 | E13: =XIRR(C55:E55,C56:E56) -> 0.23542268 | F13: =XIRR(C57:F57,C58:F58) -> 0.20825184
B16: IRR SENSITIVITY: EXIT MULTIPLE vs. EBITDA MARGIN (5-YEAR HOLD) | J16: Note: IRR sensitivity values are Excel Data Table outputs. Row input = Transaction Assumptions C38. Column input = Operating Model H10.
B17: Exit Multiple \ EBITDA Margin | C17: 0.18 | D17: 0.2 | E17: 0.22 | F17: 0.24 | G17: 0.26 | H17: 0.28 | I17: Note: The IRR sensitivity values above are outputs of a two-variable Excel Data Table (Data > What-If Analysis > Data Table). Row input cell: Transaction Assumptions C38 (Exit EV/EBITDA Multiple). Column input cell: Operating Model H10 (EBITDA Margin). To refresh, re-run the data table after changing any underlying assumptions.
B18: 8 | C18: 0.16252244 | D18: 0.1917337 | E18: 0.21833339 | F18: 0.24279451 | G18: 0.26546888 | H18: 0.28662578
B19: 9 | C19: 0.19519033 | D19: 0.22463371 | E19: 0.25149082 | F19: 0.27622268 | G19: 0.29917391 | H19: 0.32060932
B20: 10 | C20: 0.22463371 | D20: 0.25433661 | E20: 0.28146646 | F20: 0.3064762 | G20: 0.3297057 | H20: 0.35141697
B21: 11 | C21: 0.25149082 | D21: 0.28146646 | E21: 0.30887442 | F21: 0.33416212 | G21: 0.35766634 | H21: 0.37964733
B22: 12 | C22: 0.27622268 | D22: 0.3064762 | E22: 0.33416212 | F22: 0.35972412 | G22: 0.38349699 | H22: 0.40573999
B23: 13 | C23: 0.29917391 | D23: 0.3297057 | E23: 0.35766634 | F23: 0.38349699 | G23: 0.40753126 | H23: 0.43002792
B26: MoM SENSITIVITY: EXIT MULTIPLE vs. HOLD PERIOD | J26: Note: MoM sensitivity values are Excel Data Table outputs. Anchored to base case MoM (cell E12).
B27: Exit Multiple \ Hold Period | C27: 3 Years | D27: 4 Years | E27: 5 Years | F27: 6 Years | G27: 7 Years
B28: 7 | C28: 1.3279785 | D28: 1.6298844 | E28: 1.9437131 | F28: 2.2702993 | G28: 2.6105361
B29: 8.5 | C29: 1.8493874 | D29: 2.1877919 | E29: 2.5406742 | F29: 2.9090477 | G29: 3.2939968
B30: 10 | C30: 2.3707964 | D30: 2.7456995 | E30: 3.1376353 | F30: 3.5477961 | G30: 3.9774576
B31: 11.5 | C31: 2.8922053 | D31: 3.303607 | E31: 3.7345964 | F31: 4.1865444 | G31: 4.6609183
B32: 13 | C32: 3.4136142 | D32: 3.8615146 | E32: 4.3315574 | F32: 4.8252928 | G32: 5.3443791
B35: SCENARIO ANALYSIS: BEAR / BASE / BULL CASE
B36: Metric | C36: Bear Case | E36: Base Case | G36: Bull Case
B37: Revenue CAGR | C37: 0.04 | E37: 0.07 | G37: 0.1
B38: Exit EBITDA Margin | C38: 0.18 | E38: 0.227 | G38: 0.28
B39: Exit EV/EBITDA | C39: 8 | E39: 10.5 | G39: 13
B40: Exit Equity Value ($mm) | C40: =ROUND('Transaction Assumptions'!C4*(1+C37)^5*C38*C39-'Operating Model'!H23,0) -> 271 | E40: =ROUND('Transaction Assumptions'!C4*(1+E37)^5*E38*E39-'Operating Model'!H23,0) -> 876 | G40: =ROUND('Transaction Assumptions'!C4*(1+G37)^5*G38*G39,0) -> 2228
B41: Money-on-Money | C41: =C40/'Transaction Assumptions'!C22 -> 0.89144737 | E41: =E40/'Transaction Assumptions'!C22 -> 2.8815789 | G41: =G40/'Transaction Assumptions'!C22 -> 7.3289474
B42: IRR (5-Year) | C42: =XIRR(C62:C63,C64:C65) -> -0.022695121 | E42: =XIRR(E62:E63,E64:E65) -> 0.23545086 | G42: =XIRR(G62:G63,G64:G65) -> 0.48874025
B45: IRR CALCULATION: XIRR CASH FLOW SCHEDULE
B46: Cash Flow Item | C46: Entry (2024) | D46: Year 3 (2027) | E46: Year 5 (2029) | F46: Year 7 (2031)
B47: Date | C47: =DATE(2024,1,1) -> 45292 | D47: =DATE(2027,1,1) -> 46388 | E47: =DATE(2029,1,1) -> 47119 | F47: =DATE(2031,1,1) -> 47849
B48: Equity Investment (Outflow) | C48: =-'Transaction Assumptions'!C22 -> -304 | D48: =C48 -> -304 | E48: =C48 -> -304 | F48: =C48 -> -304
B49: Exit Equity Proceeds (Inflow) | C49: 0 | D49: =D11 -> 655.68 | E49: =E11 -> 875.9 | F49: =F11 -> 1144
...
